from odoo import models, fields, api, Command, _
from odoo.exceptions import ValidationError, UserError


class VeterinaryAppointment(models.Model):
    _inherit = 'veterinary.appointment'

    order_id = fields.Many2one('sale.order')
    order_count = fields.Integer(string='Order Count', compute='_compute_order_count')

    def _compute_order_count(self):
        for record in self:
            record.order_count = self.env['sale.order'].search_count([('appointment_id', '=', record.id)])

    def create_order(self):
        for record in self:
            vals = {
                'partner_id': record.partner_id.id,
                'date_order': record.date,
                'appointment_id': record.id,
                'order_line': [(0, 0, {
                    'product_id': line.product_id.id,
                    'name': line.product_id.name,
                    'product_uom_qty': line.quantity,
                    'price_unit': line.price_unit
                }) for line in record.line_ids]
            }
        order = self.env['sale.order'].create(vals)
        record.order_id = order.id
        return {
            'name': 'Sale Order',
            'type': 'ir.actions.act_window',
            'res_model': 'sale.order',
            'view_mode': 'form',
            'res_id': order.id,
        }
    
    def action_view_order(self):
    
        return {
            'name': 'Sale Order',
            'type': 'ir.actions.act_window',
            'res_model': 'sale.order',
            'view_mode': 'tree,form',
            'domain': [('appointment_id', '=', self.id)]
        }
